Workbook

Sheet README
A1: B2B Tech Hardware: SKU Pricing, Deal Desk & Margin Leakage Model
A2: Practice project by Chaewon Shin. ALL DATA IS SIMULATED for illustration; not real OEM, distributor, or company data.
A4: Business question | B4: We resell laptops, monitors and accessories to companies in 5 countries. What should each SKU cost, what should we charge, how low can Sales go on a big deal, and where are we losing margin?
A6: SHEET GUIDE
A7: Assumptions | B7: Inputs: FX, import duty, FX buffer, freight per unit by region; target and floor margin by category.
A8: SKU_Master | B8: 30 SKUs: OEM, category, tier, lifecycle, vendor cost, base OEM rebate.
A9: Price_Book | B9: 150 SKU x region rows: landed cost -> target price (USD) -> list price in local currency, plus floor price.
A10: Deal_Desk | B10: Quote checker for one big deal. Compares 'as requested' vs 'with deal-registration rebate' and returns the approval tier.
A11: FX_Scenario | B11: How much FX movement a list price can absorb before it breaks the margin floor.
A12: Orders | B12: 12 months of simulated order lines (Oct 2025 - Sep 2026) with realized margin per line.
A13: Margin_Leakage | B13: Margin bridge (list -> discounts -> cost drift -> FX -> actual) and cuts by region, category, rep, month.
A14: Assortment | B14: ABC class per category and a keep / preferred / consolidate / phase-out recommendation per SKU.
A16: COLOR LEGEND
A17: Blue text | B17: Hard-coded input you can change.
A18: Yellow fill | B18: Key lever to try first (e.g. Deal_Desk inputs, FX shock, target margins).
A19: Green text | B19: Formula pulling from another sheet.
A20: Black text | B20: Formula on the same sheet.
A22: CORE FORMULAS
A23: Landed cost (USD) | B23: Vendor cost x (1 - OEM rebate) x (1 + import duty) + freight per unit
A24: Target price (USD) | B24: Landed cost / (1 - target margin) (margin is on price, not markup on cost)
A25: List price (local) | B25: Round up to 5 of: target price x (1 + list headroom) x (1 + FX buffer) x FX rate
A26: Floor price | B26: Landed cost / (1 - floor margin). Below floor needs Finance approval.
A27: Approval tiers | B27: Margin >= target: auto-approve | floor <= margin < target: Sales Lead | 0 <= margin < floor: Finance (VP) | margin < 0: reject
A28: VAT / GST | B28: Excluded. B2B prices are quoted ex-VAT and business buyers reclaim VAT, so it does not change our margin.
A30: HEADLINE NUMBERS (live)
A31: Revenue (USD) | B31: =Margin_Leakage!F5 -> 26674169
A32: Gross margin % | B32: =Margin_Leakage!F7 -> 0.13520702
A33: Target margin % (weighted) | B33: =Margin_Leakage!F8 -> 0.13783788
A34: Shortfall vs target (USD) | B34: =Margin_Leakage!F9 -> 305416.92
A35: Discount impact (USD) | B35: =Margin_Leakage!B7 -> -1010095.3
A36: Cost increases not repriced (USD) | B36: =Margin_Leakage!B9 -> -167238.03
A37: FX impact (USD) | B37: =Margin_Leakage!B10 -> -127228.5

Sheet Assumptions
A1: Assumptions
A2: Blue = input. Rates are illustrative (simulated). FX = units of local currency per 1 USD.
A3: Region economics | F3: Freight & handling per unit (USD)
A4: Region | B4: Currency | C4: FX (local per USD) | D4: Import duty % | E4: FX buffer % | F4: Laptop | G4: Monitor | H4: Accessory
A5: US | B5: USD | C5: 1 | D5: 0 | E5: 0 | F5: 18 | G5: 25 | H5: 6
A6: UK | B6: GBP | C6: 0.79 | D6: 0 | E6: 0.02 | F6: 42 | G6: 55 | H6: 12
A7: DE | B7: EUR | C7: 0.92 | D7: 0 | E7: 0.02 | F7: 38 | G7: 50 | H7: 11
A8: CA | B8: CAD | C8: 1.37 | D8: 0 | E8: 0.02 | F8: 30 | G8: 40 | H8: 9
A9: IN | B9: INR | C9: 83.5 | D9: 0.11 | E9: 0.02 | F9: 55 | G9: 70 | H9: 15
A10: FX buffer = extra cushion built into non-USD list prices so a small currency move does not erase margin. Duty for IN is an illustrative 11% on IT hardware.
A12: Category margin policy
A13: Category | B13: Target margin | C13: Floor margin | D13: List headroom %
A14: Laptop | B14: 0.12 | C14: 0.08 | D14: 0.03
A15: Monitor | B15: 0.18 | C15: 0.12 | D15: 0.04
A16: Accessory | B16: 0.32 | C16: 0.22 | D16: 0.05
A17: Laptops carry thin margins (commoditized, price-transparent); accessories carry the margin. Gross margin on price. List headroom = room for normal negotiation built into list price, so a standard discount still lands on target.
A19: Assortment rules
A20: Class A = top cumulative revenue share up to | C20: 0.8
A21: Class B = up to | C21: 0.95
A22: Low-volume threshold (share of category units) | C22: 0.02
A23: Margin tolerance below target before flagging (pts) | C23: 0.01

Sheet SKU_Master
A1: SKU Master
A2: Vendor cost = price we pay the OEM/distributor per unit (USD, illustrative). Base rebate = standing OEM partner rebate.
A4: SKU | B4: OEM | C4: Model | D4: Category | E4: Tier | F4: Lifecycle | G4: Vendor cost (USD) | H4: Base OEM rebate %
A5: L01 | B5: Apple | C5: MacBook Air 13 M3 16GB/512GB | D5: Laptop | E5: Mainstream | F5: Active | G5: 1180 | H5: 0.01
A6: L02 | B6: Apple | C6: MacBook Pro 14 M3 Pro 18GB/512GB | D6: Laptop | E6: Premium | F6: Active | G6: 1780 | H6: 0.01
A7: L03 | B7: Apple | C7: MacBook Pro 16 M3 Max 36GB/1TB | D7: Laptop | E7: Premium | F7: Active | G7: 2950 | H7: 0.01
A8: L04 | B8: Dell | C8: Latitude 5450 i5/16GB/512GB | D8: Laptop | E8: Mainstream | F8: Active | G8: 980 | H8: 0.03
A9: L05 | B9: Dell | C9: Latitude 7450 i7/16GB/512GB | D9: Laptop | E9: Premium | F9: Active | G9: 1320 | H9: 0.03
A10: L06 | B10: Dell | C10: XPS 13 9340 Ultra 7/16GB/512GB | D10: Laptop | E10: Premium | F10: Active | G10: 1150 | H10: 0.02
A11: L07 | B11: Lenovo | C11: ThinkPad T14 Gen 5 i5/16GB/512GB | D11: Laptop | E11: Mainstream | F11: Active | G11: 1010 | H11: 0.035
A12: L08 | B12: Lenovo | C12: ThinkPad X1 Carbon Gen 12 i7/32GB/1TB | D12: Laptop | E12: Premium | F12: Active | G12: 1520 | H12: 0.035
A13: L09 | B13: Lenovo | C13: ThinkPad E14 Gen 6 i5/16GB/256GB | D13: Laptop | E13: Entry | F13: Active | G13: 720 | H13: 0.02
A14: L10 | B14: HP | C14: EliteBook 840 G11 Ultra 5/16GB/512GB | D14: Laptop | E14: Mainstream | F14: Active | G14: 1180 | H14: 0.03
A15: L11 | B15: HP | C15: ProBook 450 G10 i5/16GB/256GB | D15: Laptop | E15: Entry | F15: Active | G15: 780 | H15: 0.02
A16: L12 | B16: Microsoft | C16: Surface Laptop 6 Ultra 5/16GB/256GB | D16: Laptop | E16: Premium | F16: Active | G16: 1250 | H16: 0.015
... A34: A09 | B34: Anker | C34: 100W USB-C Charger | D34: Accessory | E34: Power | F34: Active | G34: 38 | H34: 0

Sheet Price_Book
A1: Price Book (SKU x Region)
A2: All formulas. Change Assumptions or SKU_Master and every price updates.
A4: SKU | B4: Model | C4: Category | D4: Region | E4: Currency | F4: Vendor cost (USD) | G4: OEM rebate % | H4: Net cost after rebate | I4: Duty % | J4: Duty (USD) | K4: Freight (USD) | L4: Landed cost (USD) | M4: Target margin | N4: Target price (USD) | O4: FX buffer % | P4: FX (book) | Q4: List headroom % | R4: List price (local) | S4: Floor margin | T4: Floor price (USD) | U4: Floor price (local) | V4: List margin at book FX | W4: Lookup key
A5: L01 | B5: =INDEX(SKU_Master!$C$5:$C$34,MATCH($A5,SKU_Master!$A$5:$A$34,0)) -> MacBook Air 13 M3 16GB/512GB | C5: =INDEX(SKU_Master!$D$5:$D$34,MATCH($A5,SKU_Master!$A$5:$A$34,0)) -> Laptop | D5: US | E5: =INDEX(Assumptions!$B$5:$B$9,MATCH($D5,Assumptions!$A$5:$A$9,0)) -> USD | F5: =INDEX(SKU_Master!$G$5:$G$34,MATCH($A5,SKU_Master!$A$5:$A$34,0)) -> 1180 | G5: =INDEX(SKU_Master!$H$5:$H$34,MATCH($A5,SKU_Master!$A$5:$A$34,0)) -> 0.01 | H5: =F5*(1-G5) -> 1168.2 | I5: =INDEX(Assumptions!$D$5:$D$9,MATCH($D5,Assumptions!$A$5:$A$9,0)) -> 0 | J5: =H5*I5 -> 0 | K5: =INDEX(Assumptions!$F$5:$H$9,MATCH($D5,Assumptions!$A$5:$A$9,0),MATCH($C5,Assumptions!$F$4:$H$4,0)) -> 18 | L5: =H5+J5+K5 -> 1186.2 | M5: =INDEX(Assumptions!$B$14:$B$16,MATCH($C5,Assumptions!$A$14:$A$16,0)) -> 0.12 | N5: =L5/(1-M5) -> 1347.9545 | O5: =INDEX(Assumptions!$E$5:$E$9,MATCH($D5,Assumptions!$A$5:$A$9,0)) -> 0 | P5: =INDEX(Assumptions!$C$5:$C$9,MATCH($D5,Assumptions!$A$5:$A$9,0)) -> 1 | Q5: =INDEX(Assumptions!$D$14:$D$16,MATCH($C5,Assumptions!$A$14:$A$16,0)) -> 0.03 | R5: =ROUNDUP(N5*(1+Q5)*(1+O5)*P5/5,0)*5 -> 1390 | S5: =INDEX(Assumptions!$C$14:$C$16,MATCH($C5,Assumptions!$A$14:$A$16,0)) -> 0.08 | T5: =L5/(1-S5) -> 1289.3478 | U5: =T5*(1+O5)*P5 -> 1289.3478 | V5: =IF(R5=0,0,(R5/P5-L5)/(R5/P5)) -> 0.14661871 | W5: =A5&"|"&D5 -> L01|US
A6: L01 | B6: =INDEX(SKU_Master!$C$5:$C$34,MATCH($A6,SKU_Master!$A$5:$A$34,0)) -> MacBook Air 13 M3 16GB/512GB | C6: =INDEX(SKU_Master!$D$5:$D$34,MATCH($A6,SKU_Master!$A$5:$A$34,0)) -> Laptop | D6: UK | E6: =INDEX(Assumptions!$B$5:$B$9,MATCH($D6,Assumptions!$A$5:$A$9,0)) -> GBP | F6: =INDEX(SKU_Master!$G$5:$G$34,MATCH($A6,SKU_Master!$A$5:$A$34,0)) -> 1180 | G6: =INDEX(SKU_Master!$H$5:$H$34,MATCH($A6,SKU_Master!$A$5:$A$34,0)) -> 0.01 | H6: =F6*(1-G6) -> 1168.2 | I6: =INDEX(Assumptions!$D$5:$D$9,MATCH($D6,Assumptions!$A$5:$A$9,0)) -> 0 | J6: =H6*I6 -> 0 | K6: =INDEX(Assumptions!$F$5:$H$9,MATCH($D6,Assumptions!$A$5:$A$9,0),MATCH($C6,Assumptions!$F$4:$H$4,0)) -> 42 | L6: =H6+J6+K6 -> 1210.2 | M6: =INDEX(Assumptions!$B$14:$B$16,MATCH($C6,Assumptions!$A$14:$A$16,0)) -> 0.12 | N6: =L6/(1-M6) -> 1375.2273 | O6: =INDEX(Assumptions!$E$5:$E$9,MATCH($D6,Assumptions!$A$5:$A$9,0)) -> 0.02 | P6: =INDEX(Assumptions!$C$5:$C$9,MATCH($D6,Assumptions!$A$5:$A$9,0)) -> 0.79 | Q6: =INDEX(Assumptions!$D$14:$D$16,MATCH($C6,Assumptions!$A$14:$A$16,0)) -> 0.03 | R6: =ROUNDUP(N6*(1+Q6)*(1+O6)*P6/5,0)*5 -> 1145 | S6: =INDEX(Assumptions!$C$14:$C$16,MATCH($C6,Assumptions!$A$14:$A$16,0)) -> 0.08 | T6: =L6/(1-S6) -> 1315.4348 | U6: =T6*(1+O6)*P6 -> 1059.9773 | V6: =IF(R6=0,0,(R6/P6-L6)/(R6/P6)) -> 0.16501485 | W6: =A6&"|"&D6 -> L01|UK
A7: L01 | B7: =INDEX(SKU_Master!$C$5:$C$34,MATCH($A7,SKU_Master!$A$5:$A$34,0)) -> MacBook Air 13 M3 16GB/512GB | C7: =INDEX(SKU_Master!$D$5:$D$34,MATCH($A7,SKU_Master!$A$5:$A$34,0)) -> Laptop | D7: DE | E7: =INDEX(Assumptions!$B$5:$B$9,MATCH($D7,Assumptions!$A$5:$A$9,0)) -> EUR | F7: =INDEX(SKU_Master!$G$5:$G$34,MATCH($A7,SKU_Master!$A$5:$A$34,0)) -> 1180 | G7: =INDEX(SKU_Master!$H$5:$H$34,MATCH($A7,SKU_Master!$A$5:$A$34,0)) -> 0.01 | H7: =F7*(1-G7) -> 1168.2 | I7: =INDEX(Assumptions!$D$5:$D$9,MATCH($D7,Assumptions!$A$5:$A$9,0)) -> 0 | J7: =H7*I7 -> 0 | K7: =INDEX(Assumptions!$F$5:$H$9,MATCH($D7,Assumptions!$A$5:$A$9,0),MATCH($C7,Assumptions!$F$4:$H$4,0)) -> 38 | L7: =H7+J7+K7 -> 1206.2 | M7: =INDEX(Assumptions!$B$14:$B$16,MATCH($C7,Assumptions!$A$14:$A$16,0)) -> 0.12 | N7: =L7/(1-M7) -> 1370.6818 | O7: =INDEX(Assumptions!$E$5:$E$9,MATCH($D7,Assumptions!$A$5:$A$9,0)) -> 0.02 | P7: =INDEX(Assumptions!$C$5:$C$9,MATCH($D7,Assumptions!$A$5:$A$9,0)) -> 0.92 | Q7: =INDEX(Assumptions!$D$14:$D$16,MATCH($C7,Assumptions!$A$14:$A$16,0)) -> 0.03 | R7: =ROUNDUP(N7*(1+Q7)*(1+O7)*P7/5,0)*5 -> 1325 | S7: =INDEX(Assumptions!$C$14:$C$16,MATCH($C7,Assumptions!$A$14:$A$16,0)) -> 0.08 | T7: =L7/(1-S7) -> 1311.087 | U7: =T7*(1+O7)*P7 -> 1230.324 | V7: =IF(R7=0,0,(R7/P7-L7)/(R7/P7)) -> 0.16248755 | W7: =A7&"|"&D7 -> L01|DE
A8: L01 | B8: =INDEX(SKU_Master!$C$5:$C$34,MATCH($A8,SKU_Master!$A$5:$A$34,0)) -> MacBook Air 13 M3 16GB/512GB | C8: =INDEX(SKU_Master!$D$5:$D$34,MATCH($A8,SKU_Master!$A$5:$A$34,0)) -> Laptop | D8: CA | E8: =INDEX(Assumptions!$B$5:$B$9,MATCH($D8,Assumptions!$A$5:$A$9,0)) -> CAD | F8: =INDEX(SKU_Master!$G$5:$G$34,MATCH($A8,SKU_Master!$A$5:$A$34,0)) -> 1180 | G8: =INDEX(SKU_Master!$H$5:$H$34,MATCH($A8,SKU_Master!$A$5:$A$34,0)) -> 0.01 | H8: =F8*(1-G8) -> 1168.2 | I8: =INDEX(Assumptions!$D$5:$D$9,MATCH($D8,Assumptions!$A$5:$A$9,0)) -> 0 | J8: =H8*I8 -> 0 | K8: =INDEX(Assumptions!$F$5:$H$9,MATCH($D8,Assumptions!$A$5:$A$9,0),MATCH($C8,Assumptions!$F$4:$H$4,0)) -> 30 | L8: =H8+J8+K8 -> 1198.2 | M8: =INDEX(Assumptions!$B$14:$B$16,MATCH($C8,Assumptions!$A$14:$A$16,0)) -> 0.12 | N8: =L8/(1-M8) -> 1361.5909 | O8: =INDEX(Assumptions!$E$5:$E$9,MATCH($D8,Assumptions!$A$5:$A$9,0)) -> 0.02 | P8: =INDEX(Assumptions!$C$5:$C$9,MATCH($D8,Assumptions!$A$5:$A$9,0)) -> 1.37 | Q8: =INDEX(Assumptions!$D$14:$D$16,MATCH($C8,Assumptions!$A$14:$A$16,0)) -> 0.03 | R8: =ROUNDUP(N8*(1+Q8)*(1+O8)*P8/5,0)*5 -> 1960 | S8: =INDEX(Assumptions!$C$14:$C$16,MATCH($C8,Assumptions!$A$14:$A$16,0)) -> 0.08 | T8: =L8/(1-S8) -> 1302.3913 | U8: =T8*(1+O8)*P8 -> 1819.9616 | V8: =IF(R8=0,0,(R8/P8-L8)/(R8/P8)) -> 0.16248265 | W8: =A8&"|"&D8 -> L01|CA
A9: L01 | B9: =INDEX(SKU_Master!$C$5:$C$34,MATCH($A9,SKU_Master!$A$5:$A$34,0)) -> MacBook Air 13 M3 16GB/512GB | C9: =INDEX(SKU_Master!$D$5:$D$34,MATCH($A9,SKU_Master!$A$5:$A$34,0)) -> Laptop | D9: IN | E9: =INDEX(Assumptions!$B$5:$B$9,MATCH($D9,Assumptions!$A$5:$A$9,0)) -> INR | F9: =INDEX(SKU_Master!$G$5:$G$34,MATCH($A9,SKU_Master!$A$5:$A$34,0)) -> 1180 | G9: =INDEX(SKU_Master!$H$5:$H$34,MATCH($A9,SKU_Master!$A$5:$A$34,0)) -> 0.01 | H9: =F9*(1-G9) -> 1168.2 | I9: =INDEX(Assumptions!$D$5:$D$9,MATCH($D9,Assumptions!$A$5:$A$9,0)) -> 0.11 | J9: =H9*I9 -> 128.502 | K9: =INDEX(Assumptions!$F$5:$H$9,MATCH($D9,Assumptions!$A$5:$A$9,0),MATCH($C9,Assumptions!$F$4:$H$4,0)) -> 55 | L9: =H9+J9+K9 -> 1351.702 | M9: =INDEX(Assumptions!$B$14:$B$16,MATCH($C9,Assumptions!$A$14:$A$16,0)) -> 0.12 | N9: =L9/(1-M9) -> 1536.025 | O9: =INDEX(Assumptions!$E$5:$E$9,MATCH($D9,Assumptions!$A$5:$A$9,0)) -> 0.02 | P9: =INDEX(Assumptions!$C$5:$C$9,MATCH($D9,Assumptions!$A$5:$A$9,0)) -> 83.5 | Q9: =INDEX(Assumptions!$D$14:$D$16,MATCH($C9,Assumptions!$A$14:$A$16,0)) -> 0.03 | R9: =ROUNDUP(N9*(1+Q9)*(1+O9)*P9/5,0)*5 -> 134750 | S9: =INDEX(Assumptions!$C$14:$C$16,MATCH($C9,Assumptions!$A$14:$A$16,0)) -> 0.08 | T9: =L9/(1-S9) -> 1469.2413 | U9: =T9*(1+O9)*P9 -> 125135.28 | V9: =IF(R9=0,0,(R9/P9-L9)/(R9/P9)) -> 0.16239616 | W9: =A9&"|"&D9 -> L01|IN
A10: L02 | B10: =INDEX(SKU_Master!$C$5:$C$34,MATCH($A10,SKU_Master!$A$5:$A$34,0)) -> MacBook Pro 14 M3 Pro 18GB/512GB | C10: =INDEX(SKU_Master!$D$5:$D$34,MATCH($A10,SKU_Master!$A$5:$A$34,0)) -> Laptop | D10: US | E10: =INDEX(Assumptions!$B$5:$B$9,MATCH($D10,Assumptions!$A$5:$A$9,0)) -> USD | F10: =INDEX(SKU_Master!$G$5:$G$34,MATCH($A10,SKU_Master!$A$5:$A$34,0)) -> 1780 | G10: =INDEX(SKU_Master!$H$5:$H$34,MATCH($A10,SKU_Master!$A$5:$A$34,0)) -> 0.01 | H10: =F10*(1-G10) -> 1762.2 | I10: =INDEX(Assumptions!$D$5:$D$9,MATCH($D10,Assumptions!$A$5:$A$9,0)) -> 0 | J10: =H10*I10 -> 0 | K10: =INDEX(Assumptions!$F$5:$H$9,MATCH($D10,Assumptions!$A$5:$A$9,0),MATCH($C10,Assumptions!$F$4:$H$4,0)) -> 18 | L10: =H10+J10+K10 -> 1780.2 | M10: =INDEX(Assumptions!$B$14:$B$16,MATCH($C10,Assumptions!$A$14:$A$16,0)) -> 0.12 | N10: =L10/(1-M10) -> 2022.9545 | O10: =INDEX(Assumptions!$E$5:$E$9,MATCH($D10,Assumptions!$A$5:$A$9,0)) -> 0 | P10: =INDEX(Assumptions!$C$5:$C$9,MATCH($D10,Assumptions!$A$5:$A$9,0)) -> 1 | Q10: =INDEX(Assumptions!$D$14:$D$16,MATCH($C10,Assumptions!$A$14:$A$16,0)) -> 0.03 | R10: =ROUNDUP(N10*(1+Q10)*(1+O10)*P10/5,0)*5 -> 2085 | S10: =INDEX(Assumptions!$C$14:$C$16,MATCH($C10,Assumptions!$A$14:$A$16,0)) -> 0.08 | T10: =L10/(1-S10) -> 1935 | U10: =T10*(1+O10)*P10 -> 1935 | V10: =IF(R10=0,0,(R10/P10-L10)/(R10/P10)) -> 0.14618705 | W10: =A10&"|"&D10 -> L02|US
A11: L02 | B11: =INDEX(SKU_Master!$C$5:$C$34,MATCH($A11,SKU_Master!$A$5:$A$34,0)) -> MacBook Pro 14 M3 Pro 18GB/512GB | C11: =INDEX(SKU_Master!$D$5:$D$34,MATCH($A11,SKU_Master!$A$5:$A$34,0)) -> Laptop | D11: UK | E11: =INDEX(Assumptions!$B$5:$B$9,MATCH($D11,Assumptions!$A$5:$A$9,0)) -> GBP | F11: =INDEX(SKU_Master!$G$5:$G$34,MATCH($A11,SKU_Master!$A$5:$A$34,0)) -> 1780 | G11: =INDEX(SKU_Master!$H$5:$H$34,MATCH($A11,SKU_Master!$A$5:$A$34,0)) -> 0.01 | H11: =F11*(1-G11) -> 1762.2 | I11: =INDEX(Assumptions!$D$5:$D$9,MATCH($D11,Assumptions!$A$5:$A$9,0)) -> 0 | J11: =H11*I11 -> 0 | K11: =INDEX(Assumptions!$F$5:$H$9,MATCH($D11,Assumptions!$A$5:$A$9,0),MATCH($C11,Assumptions!$F$4:$H$4,0)) -> 42 | L11: =H11+J11+K11 -> 1804.2 | M11: =INDEX(Assumptions!$B$14:$B$16,MATCH($C11,Assumptions!$A$14:$A$16,0)) -> 0.12 | N11: =L11/(1-M11) -> 2050.2273 | O11: =INDEX(Assumptions!$E$5:$E$9,MATCH($D11,Assumptions!$A$5:$A$9,0)) -> 0.02 | P11: =INDEX(Assumptions!$C$5:$C$9,MATCH($D11,Assumptions!$A$5:$A$9,0)) -> 0.79 | Q11: =INDEX(Assumptions!$D$14:$D$16,MATCH($C11,Assumptions!$A$14:$A$16,0)) -> 0.03 | R11: =ROUNDUP(N11*(1+Q11)*(1+O11)*P11/5,0)*5 -> 1705 | S11: =INDEX(Assumptions!$C$14:$C$16,MATCH($C11,Assumptions!$A$14:$A$16,0)) -> 0.08 | T11: =L11/(1-S11) -> 1961.087 | U11: =T11*(1+O11)*P11 -> 1580.2439 | V11: =IF(R11=0,0,(R11/P11-L11)/(R11/P11)) -> 0.16403636 | W11: =A11&"|"&D11 -> L02|UK
A12: L02 | B12: =INDEX(SKU_Master!$C$5:$C$34,MATCH($A12,SKU_Master!$A$5:$A$34,0)) -> MacBook Pro 14 M3 Pro 18GB/512GB | C12: =INDEX(SKU_Master!$D$5:$D$34,MATCH($A12,SKU_Master!$A$5:$A$34,0)) -> Laptop | D12: DE | E12: =INDEX(Assumptions!$B$5:$B$9,MATCH($D12,Assumptions!$A$5:$A$9,0)) -> EUR | F12: =INDEX(SKU_Master!$G$5:$G$34,MATCH($A12,SKU_Master!$A$5:$A$34,0)) -> 1780 | G12: =INDEX(SKU_Master!$H$5:$H$34,MATCH($A12,SKU_Master!$A$5:$A$34,0)) -> 0.01 | H12: =F12*(1-G12) -> 1762.2 | I12: =INDEX(Assumptions!$D$5:$D$9,MATCH($D12,Assumptions!$A$5:$A$9,0)) -> 0 | J12: =H12*I12 -> 0 | K12: =INDEX(Assumptions!$F$5:$H$9,MATCH($D12,Assumptions!$A$5:$A$9,0),MATCH($C12,Assumptions!$F$4:$H$4,0)) -> 38 | L12: =H12+J12+K12 -> 1800.2 | M12: =INDEX(Assumptions!$B$14:$B$16,MATCH($C12,Assumptions!$A$14:$A$16,0)) -> 0.12 | N12: =L12/(1-M12) -> 2045.6818 | O12: =INDEX(Assumptions!$E$5:$E$9,MATCH($D12,Assumptions!$A$5:$A$9,0)) -> 0.02 | P12: =INDEX(Assumptions!$C$5:$C$9,MATCH($D12,Assumptions!$A$5:$A$9,0)) -> 0.92 | Q12: =INDEX(Assumptions!$D$14:$D$16,MATCH($C12,Assumptions!$A$14:$A$16,0)) -> 0.03 | R12: =ROUNDUP(N12*(1+Q12)*(1+O12)*P12/5,0)*5 -> 1980 | S12: =INDEX(Assumptions!$C$14:$C$16,MATCH($C12,Assumptions!$A$14:$A$16,0)) -> 0.08 | T12: =L12/(1-S12) -> 1956.7391 | U12: =T12*(1+O12)*P12 -> 1836.204 | V12: =IF(R12=0,0,(R12/P12-L12)/(R12/P12)) -> 0.16354343 | W12: =A12&"|"&D12 -> L02|DE
A13: L02 | B13: =INDEX(SKU_Master!$C$5:$C$34,MATCH($A13,SKU_Master!$A$5:$A$34,0)) -> MacBook Pro 14 M3 Pro 18GB/512GB | C13: =INDEX(SKU_Master!$D$5:$D$34,MATCH($A13,SKU_Master!$A$5:$A$34,0)) -> Laptop | D13: CA | E13: =INDEX(Assumptions!$B$5:$B$9,MATCH($D13,Assumptions!$A$5:$A$9,0)) -> CAD | F13: =INDEX(SKU_Master!$G$5:$G$34,MATCH($A13,SKU_Master!$A$5:$A$34,0)) -> 1780 | G13: =INDEX(SKU_Master!$H$5:$H$34,MATCH($A13,SKU_Master!$A$5:$A$34,0)) -> 0.01 | H13: =F13*(1-G13) -> 1762.2 | I13: =INDEX(Assumptions!$D$5:$D$9,MATCH($D13,Assumptions!$A$5:$A$9,0)) -> 0 | J13: =H13*I13 -> 0 | K13: =INDEX(Assumptions!$F$5:$H$9,MATCH($D13,Assumptions!$A$5:$A$9,0),MATCH($C13,Assumptions!$F$4:$H$4,0)) -> 30 | L13: =H13+J13+K13 -> 1792.2 | M13: =INDEX(Assumptions!$B$14:$B$16,MATCH($C13,Assumptions!$A$14:$A$16,0)) -> 0.12 | N13: =L13/(1-M13) -> 2036.5909 | O13: =INDEX(Assumptions!$E$5:$E$9,MATCH($D13,Assumptions!$A$5:$A$9,0)) -> 0.02 | P13: =INDEX(Assumptions!$C$5:$C$9,MATCH($D13,Assumptions!$A$5:$A$9,0)) -> 1.37 | Q13: =INDEX(Assumptions!$D$14:$D$16,MATCH($C13,Assumptions!$A$14:$A$16,0)) -> 0.03 | R13: =ROUNDUP(N13*(1+Q13)*(1+O13)*P13/5,0)*5 -> 2935 | S13: =INDEX(Assumptions!$C$14:$C$16,MATCH($C13,Assumptions!$A$14:$A$16,0)) -> 0.08 | T13: =L13/(1-S13) -> 1948.0435 | U13: =T13*(1+O13)*P13 -> 2722.196 | V13: =IF(R13=0,0,(R13/P13-L13)/(R13/P13)) -> 0.16343646 | W13: =A13&"|"&D13 -> L02|CA
A14: L02 | B14: =INDEX(SKU_Master!$C$5:$C$34,MATCH($A14,SKU_Master!$A$5:$A$34,0)) -> MacBook Pro 14 M3 Pro 18GB/512GB | C14: =INDEX(SKU_Master!$D$5:$D$34,MATCH($A14,SKU_Master!$A$5:$A$34,0)) -> Laptop | D14: IN | E14: =INDEX(Assumptions!$B$5:$B$9,MATCH($D14,Assumptions!$A$5:$A$9,0)) -> INR | F14: =INDEX(SKU_Master!$G$5:$G$34,MATCH($A14,SKU_Master!$A$5:$A$34,0)) -> 1780 | G14: =INDEX(SKU_Master!$H$5:$H$34,MATCH($A14,SKU_Master!$A$5:$A$34,0)) -> 0.01 | H14: =F14*(1-G14) -> 1762.2 | I14: =INDEX(Assumptions!$D$5:$D$9,MATCH($D14,Assumptions!$A$5:$A$9,0)) -> 0.11 | J14: =H14*I14 -> 193.842 | K14: =INDEX(Assumptions!$F$5:$H$9,MATCH($D14,Assumptions!$A$5:$A$9,0),MATCH($C14,Assumptions!$F$4:$H$4,0)) -> 55 | L14: =H14+J14+K14 -> 2011.042 | M14: =INDEX(Assumptions!$B$14:$B$16,MATCH($C14,Assumptions!$A$14:$A$16,0)) -> 0.12 | N14: =L14/(1-M14) -> 2285.275 | O14: =INDEX(Assumptions!$E$5:$E$9,MATCH($D14,Assumptions!$A$5:$A$9,0)) -> 0.02 | P14: =INDEX(Assumptions!$C$5:$C$9,MATCH($D14,Assumptions!$A$5:$A$9,0)) -> 83.5 | Q14: =INDEX(Assumptions!$D$14:$D$16,MATCH($C14,Assumptions!$A$14:$A$16,0)) -> 0.03 | R14: =ROUNDUP(N14*(1+Q14)*(1+O14)*P14/5,0)*5 -> 200480 | S14: =INDEX(Assumptions!$C$14:$C$16,MATCH($C14,Assumptions!$A$14:$A$16,0)) -> 0.08 | T14: =L14/(1-S14) -> 2185.9152 | U14: =T14*(1+O14)*P14 -> 186174.4 | V14: =IF(R14=0,0,(R14/P14-L14)/(R14/P14)) -> 0.1624002 | W14: =A14&"|"&D14 -> L02|IN
A15: L03 | B15: =INDEX(SKU_Master!$C$5:$C$34,MATCH($A15,SKU_Master!$A$5:$A$34,0)) -> MacBook Pro 16 M3 Max 36GB/1TB | C15: =INDEX(SKU_Master!$D$5:$D$34,MATCH($A15,SKU_Master!$A$5:$A$34,0)) -> Laptop | D15: US | E15: =INDEX(Assumptions!$B$5:$B$9,MATCH($D15,Assumptions!$A$5:$A$9,0)) -> USD | F15: =INDEX(SKU_Master!$G$5:$G$34,MATCH($A15,SKU_Master!$A$5:$A$34,0)) -> 2950 | G15: =INDEX(SKU_Master!$H$5:$H$34,MATCH($A15,SKU_Master!$A$5:$A$34,0)) -> 0.01 | H15: =F15*(1-G15) -> 2920.5 | I15: =INDEX(Assumptions!$D$5:$D$9,MATCH($D15,Assumptions!$A$5:$A$9,0)) -> 0 | J15: =H15*I15 -> 0 | K15: =INDEX(Assumptions!$F$5:$H$9,MATCH($D15,Assumptions!$A$5:$A$9,0),MATCH($C15,Assumptions!$F$4:$H$4,0)) -> 18 | L15: =H15+J15+K15 -> 2938.5 | M15: =INDEX(Assumptions!$B$14:$B$16,MATCH($C15,Assumptions!$A$14:$A$16,0)) -> 0.12 | N15: =L15/(1-M15) -> 3339.2045 | O15: =INDEX(Assumptions!$E$5:$E$9,MATCH($D15,Assumptions!$A$5:$A$9,0)) -> 0 | P15: =INDEX(Assumptions!$C$5:$C$9,MATCH($D15,Assumptions!$A$5:$A$9,0)) -> 1 | Q15: =INDEX(Assumptions!$D$14:$D$16,MATCH($C15,Assumptions!$A$14:$A$16,0)) -> 0.03 | R15: =ROUNDUP(N15*(1+Q15)*(1+O15)*P15/5,0)*5 -> 3440 | S15: =INDEX(Assumptions!$C$14:$C$16,MATCH($C15,Assumptions!$A$14:$A$16,0)) -> 0.08 | T15: =L15/(1-S15) -> 3194.0217 | U15: =T15*(1+O15)*P15 -> 3194.0217 | V15: =IF(R15=0,0,(R15/P15-L15)/(R15/P15)) -> 0.14578488 | W15: =A15&"|"&D15 -> L03|US
A16: L03 | B16: =INDEX(SKU_Master!$C$5:$C$34,MATCH($A16,SKU_Master!$A$5:$A$34,0)) -> MacBook Pro 16 M3 Max 36GB/1TB | C16: =INDEX(SKU_Master!$D$5:$D$34,MATCH($A16,SKU_Master!$A$5:$A$34,0)) -> Laptop | D16: UK | E16: =INDEX(Assumptions!$B$5:$B$9,MATCH($D16,Assumptions!$A$5:$A$9,0)) -> GBP | F16: =INDEX(SKU_Master!$G$5:$G$34,MATCH($A16,SKU_Master!$A$5:$A$34,0)) -> 2950 | G16: =INDEX(SKU_Master!$H$5:$H$34,MATCH($A16,SKU_Master!$A$5:$A$34,0)) -> 0.01 | H16: =F16*(1-G16) -> 2920.5 | I16: =INDEX(Assumptions!$D$5:$D$9,MATCH($D16,Assumptions!$A$5:$A$9,0)) -> 0 | J16: =H16*I16 -> 0 | K16: =INDEX(Assumptions!$F$5:$H$9,MATCH($D16,Assumptions!$A$5:$A$9,0),MATCH($C16,Assumptions!$F$4:$H$4,0)) -> 42 | L16: =H16+J16+K16 -> 2962.5 | M16: =INDEX(Assumptions!$B$14:$B$16,MATCH($C16,Assumptions!$A$14:$A$16,0)) -> 0.12 | N16: =L16/(1-M16) -> 3366.4773 | O16: =INDEX(Assumptions!$E$5:$E$9,MATCH($D16,Assumptions!$A$5:$A$9,0)) -> 0.02 | P16: =INDEX(Assumptions!$C$5:$C$9,MATCH($D16,Assumptions!$A$5:$A$9,0)) -> 0.79 | Q16: =INDEX(Assumptions!$D$14:$D$16,MATCH($C16,Assumptions!$A$14:$A$16,0)) -> 0.03 | R16: =ROUNDUP(N16*(1+Q16)*(1+O16)*P16/5,0)*5 -> 2795 | S16: =INDEX(Assumptions!$C$14:$C$16,MATCH($C16,Assumptions!$A$14:$A$16,0)) -> 0.08 | T16: =L16/(1-S16) -> 3220.1087 | U16: =T16*(1+O16)*P16 -> 2594.7636 | V16: =IF(R16=0,0,(R16/P16-L16)/(R16/P16)) -> 0.16265653 | W16: =A16&"|"&D16 -> L03|UK
... A154: A09 | B154: =INDEX(SKU_Master!$C$5:$C$34,MATCH($A154,SKU_Master!$A$5:$A$34,0)) -> 100W USB-C Charger | C154: =INDEX(SKU_Master!$D$5:$D$34,MATCH($A154,SKU_Master!$A$5:$A$34,0)) -> Accessory | D154: IN | E154: =INDEX(Assumptions!$B$5:$B$9,MATCH($D154,Assumptions!$A$5:$A$9,0)) -> INR | F154: =INDEX(SKU_Master!$G$5:$G$34,MATCH($A154,SKU_Master!$A$5:$A$34,0)) -> 38 | G154: =INDEX(SKU_Master!$H$5:$H$34,MATCH($A154,SKU_Master!$A$5:$A$34,0)) -> 0 | H154: =F154*(1-G154) -> 38 | I154: =INDEX(Assumptions!$D$5:$D$9,MATCH($D154,Assumptions!$A$5:$A$9,0)) -> 0.11 | J154: =H154*I154 -> 4.18 | K154: =INDEX(Assumptions!$F$5:$H$9,MATCH($D154,Assumptions!$A$5:$A$9,0),MATCH($C154,Assumptions!$F$4:$H$4,0)) -> 15 | L154: =H154+J154+K154 -> 57.18 | M154: =INDEX(Assumptions!$B$14:$B$16,MATCH($C154,Assumptions!$A$14:$A$16,0)) -> 0.32 | N154: =L154/(1-M154) -> 84.088235 | O154: =INDEX(Assumptions!$E$5:$E$9,MATCH($D154,Assumptions!$A$5:$A$9,0)) -> 0.02 | P154: =INDEX(Assumptions!$C$5:$C$9,MATCH($D154,Assumptions!$A$5:$A$9,0)) -> 83.5 | Q154: =INDEX(Assumptions!$D$14:$D$16,MATCH($C154,Assumptions!$A$14:$A$16,0)) -> 0.05 | R154: =ROUNDUP(N154*(1+Q154)*(1+O154)*P154/5,0)*5 -> 7520 | S154: =INDEX(Assumptions!$C$14:$C$16,MATCH($C154,Assumptions!$A$14:$A$16,0)) -> 0.22 | T154: =L154/(1-S154) -> 73.307692 | U154: =T154*(1+O154)*P154 -> 6243.6162 | V154: =IF(R154=0,0,(R154/P154-L154)/(R154/P154)) -> 0.3650891 | W154: =A154&"|"&D154 -> A09|IN
A156: List price is in local currency, ex-VAT. 'List margin at book FX' is above target by design: list headroom, FX buffer and rounding leave room to negotiate.

Sheet Deal_Desk
A1: Deal Desk: special-pricing check
A2: Yellow cells are inputs. Example: a customer asks for 500 ThinkPad X1 Carbon at $1,600 each.
B4: Deal inputs
B5: SKU | C5: L08
B6: Region | C6: US
B7: Quantity (units) | C7: 500
B8: Requested unit price (local currency, ex-VAT) | C8: 1600
B9: Model | C9: =INDEX(SKU_Master!$C$5:$C$34,MATCH($C$5,SKU_Master!$A$5:$A$34,0)) -> ThinkPad X1 Carbon Gen 12 i7/32GB/1TB
B10: Category | C10: =INDEX(SKU_Master!$D$5:$D$34,MATCH($C$5,SKU_Master!$A$5:$A$34,0)) -> Laptop
B11: Currency | C11: =INDEX(Assumptions!$B$5:$B$9,MATCH($C$6,Assumptions!$A$5:$A$9,0)) -> USD
B13: Scenario | C13: A: As requested | D13: B: + deal registration | E13: What it means
B14: Extra OEM deal-registration rebate % | C14: 0 | D14: 0.02 | E14: OEMs give extra rebate when a big deal is registered with them first.
B15: Volume freight discount % | C15: 0 | D15: 0.2 | E15: Consolidated shipment of 500 units is cheaper per unit.
B16: Price book list price (local) | C16: =INDEX(Price_Book!$R$5:$R$154,MATCH($C$5&"|"&$C$6,Price_Book!$W$5:$W$154,0)) -> 1740 | D16: =INDEX(Price_Book!$R$5:$R$154,MATCH($C$5&"|"&$C$6,Price_Book!$W$5:$W$154,0)) -> 1740 | E16: Standard price before any discount.
B17: Discount vs list | C17: =IF(C16=0,0,1-$C$8/C16) -> 0.08045977 | D17: =IF(D16=0,0,1-$C$8/D16) -> 0.08045977
B18: Vendor cost (USD) | C18: =INDEX(SKU_Master!$G$5:$G$34,MATCH($C$5,SKU_Master!$A$5:$A$34,0)) -> 1520 | D18: =INDEX(SKU_Master!$G$5:$G$34,MATCH($C$5,SKU_Master!$A$5:$A$34,0)) -> 1520
B19: Net cost after base + extra rebate (USD) | C19: =C18*(1-INDEX(SKU_Master!$H$5:$H$34,MATCH($C$5,SKU_Master!$A$5:$A$34,0))-C14) -> 1466.8 | D19: =D18*(1-INDEX(SKU_Master!$H$5:$H$34,MATCH($C$5,SKU_Master!$A$5:$A$34,0))-D14) -> 1436.4 | E19: Effective vendor cost.
B20: Import duty (USD) | C20: =C19*INDEX(Assumptions!$D$5:$D$9,MATCH($C$6,Assumptions!$A$5:$A$9,0)) -> 0 | D20: =D19*INDEX(Assumptions!$D$5:$D$9,MATCH($C$6,Assumptions!$A$5:$A$9,0)) -> 0
B21: Freight per unit (USD) | C21: =INDEX(Assumptions!$F$5:$H$9,MATCH($C$6,Assumptions!$A$5:$A$9,0),MATCH($C$10,Assumptions!$F$4:$H$4,0))*(1-C15) -> 18 | D21: =INDEX(Assumptions!$F$5:$H$9,MATCH($C$6,Assumptions!$A$5:$A$9,0),MATCH($C$10,Assumptions!$F$4:$H$4,0))*(1-D15) -> 14.4
B22: Landed cost per unit (USD) | C22: =C19+C20+C21 -> 1484.8 | D22: =D19+D20+D21 -> 1450.8
B23: FX (book, local per USD) | C23: =INDEX(Assumptions!$C$5:$C$9,MATCH($C$6,Assumptions!$A$5:$A$9,0)) -> 1 | D23: =INDEX(Assumptions!$C$5:$C$9,MATCH($C$6,Assumptions!$A$5:$A$9,0)) -> 1
B24: Requested price (USD) | C24: =$C$8/C23 -> 1600 | D24: =$C$8/D23 -> 1600
B25: Gross profit per unit (USD) | C25: =C24-C22 -> 115.2 | D25: =D24-D22 -> 149.2
B26: Deal margin % | C26: =IF(C24=0,0,C25/C24) -> 0.072 | D26: =IF(D24=0,0,D25/D24) -> 0.09325 | E26: Gross margin on price.
B27: Target margin | C27: =INDEX(Assumptions!$B$14:$B$16,MATCH($C$10,Assumptions!$A$14:$A$16,0)) -> 0.12 | D27: =INDEX(Assumptions!$B$14:$B$16,MATCH($C$10,Assumptions!$A$14:$A$16,0)) -> 0.12
B28: Floor margin | C28: =INDEX(Assumptions!$C$14:$C$16,MATCH($C$10,Assumptions!$A$14:$A$16,0)) -> 0.08 | D28: =INDEX(Assumptions!$C$14:$C$16,MATCH($C$10,Assumptions!$A$14:$A$16,0)) -> 0.08
B29: Total deal revenue (USD) | C29: =C24*$C$7 -> 800000 | D29: =D24*$C$7 -> 800000
B30: Total deal gross profit (USD) | C30: =C25*$C$7 -> 57600 | D30: =D25*$C$7 -> 74600
B31: APPROVAL | C31: =IF(C26<0,"Reject",IF(C26<C28,"Finance (VP) approval",IF(C26<C27,"Sales Lead approval","Auto-approve"))) -> Finance (VP) approval | D31: =IF(D26<0,"Reject",IF(D26<D28,"Finance (VP) approval",IF(D26<D27,"Sales Lead approval","Auto-approve"))) -> Sales Lead approval | E31: Guardrail tier from the margin policy.
B32: Lowest price at floor margin (local) | C32: =C22/(1-C28)*C23 -> 1613.913 | D32: =D22/(1-D28)*D23 -> 1576.9565 | E32: Walk-away price without Finance.
B33: Counter-offer at target margin (local) | C33: =ROUNDUP(C22/(1-C27)*C23/5,0)*5 -> 1690 | D33: =ROUNDUP(D22/(1-D27)*D23/5,0)*5 -> 1650 | E33: Price that keeps target margin.
B34: Max discount vs list at floor | C34: =IF(C16=0,0,1-C32/C16) -> 0.072463768 | D34: =IF(D16=0,0,1-D32/D16) -> 0.093703148
B36: Take-away
B37: ="Scenario A margin "&TEXT(C26,"0.0%")&" -> "&C31&". Registering the deal and consolidating freight lifts it to "&TEXT(D26,"0.0%")&" -> "&D31&", adding "&TEXT(D30-C30,"$#,##0")&" gross profit at the same customer price." -> Scenario A margin 7.2% -> Finance (VP) approval. Registering the deal and consolidating freight lifts it to 9.3% -> Sales Lead approval, adding $17,000 gross profit at the same customer price.
B39: Note: deal desk prices at book FX with no FX buffer; for non-USD deals, add the region's buffer or set a short quote validity.

Sheet FX_Scenario
A1: FX Scenario: how much currency movement can a list price absorb?
A2: Positive shock = local currency weakens (more local units per USD), so each local price is worth fewer dollars.
B4: SKU | C4: L01
B5: Region | C5: UK
B6: Model | C6: =INDEX(SKU_Master!$C$5:$C$34,MATCH($C$4,SKU_Master!$A$5:$A$34,0)) -> MacBook Air 13 M3 16GB/512GB
B7: List price (local) | C7: =INDEX(Price_Book!$R$5:$R$154,MATCH($C$4&"|"&$C$5,Price_Book!$W$5:$W$154,0)) -> 1145
B8: Landed cost (USD) | C8: =INDEX(Price_Book!$L$5:$L$154,MATCH($C$4&"|"&$C$5,Price_Book!$W$5:$W$154,0)) -> 1210.2
B9: Book FX (local per USD) | C9: =INDEX(Price_Book!$P$5:$P$154,MATCH($C$4&"|"&$C$5,Price_Book!$W$5:$W$154,0)) -> 0.79
B10: Floor margin | C10: =INDEX(Price_Book!$S$5:$S$154,MATCH($C$4&"|"&$C$5,Price_Book!$W$5:$W$154,0)) -> 0.08
B11: Break-even FX at floor margin | C11: =C7/(C8/(1-C10)) -> 0.87043464
B12: FX move absorbed before hitting floor | C12: =C11/C9-1 -> 0.101816
B14: FX shock | C14: FX rate | D14: Price in USD | E14: Gross profit / unit (USD) | F14: Margin % | G14: Status
B15: -0.1 | C15: =$C$9*(1+B15) -> 0.711 | D15: =$C$7/C15 -> 1610.4079 | E15: =D15-$C$8 -> 400.20788 | F15: =IF(D15=0,0,E15/D15) -> 0.24851336 | G15: =IF(F15<0,"Loss",IF(F15<$C$10,"Below floor","OK")) -> OK
B16: -0.075 | C16: =$C$9*(1+B16) -> 0.73075 | D16: =$C$7/C16 -> 1566.8833 | E16: =D16-$C$8 -> 356.68334 | F16: =IF(D16=0,0,E16/D16) -> 0.22763873 | G16: =IF(F16<0,"Loss",IF(F16<$C$10,"Below floor","OK")) -> OK
B17: -0.05 | C17: =$C$9*(1+B17) -> 0.7505 | D17: =$C$7/C17 -> 1525.6496 | E17: =D17-$C$8 -> 315.44957 | F17: =IF(D17=0,0,E17/D17) -> 0.2067641 | G17: =IF(F17<0,"Loss",IF(F17<$C$10,"Below floor","OK")) -> OK
B18: -0.025 | C18: =$C$9*(1+B18) -> 0.77025 | D18: =$C$7/C18 -> 1486.5303 | E18: =D18-$C$8 -> 276.33035 | F18: =IF(D18=0,0,E18/D18) -> 0.18588948 | G18: =IF(F18<0,"Loss",IF(F18<$C$10,"Below floor","OK")) -> OK
B19: 0 | C19: =$C$9*(1+B19) -> 0.79 | D19: =$C$7/C19 -> 1449.3671 | E19: =D19-$C$8 -> 239.16709 | F19: =IF(D19=0,0,E19/D19) -> 0.16501485 | G19: =IF(F19<0,"Loss",IF(F19<$C$10,"Below floor","OK")) -> OK
B20: 0.025 | C20: =$C$9*(1+B20) -> 0.80975 | D20: =$C$7/C20 -> 1414.0167 | E20: =D20-$C$8 -> 203.81667 | F20: =IF(D20=0,0,E20/D20) -> 0.14414022 | G20: =IF(F20<0,"Loss",IF(F20<$C$10,"Below floor","OK")) -> OK
B21: 0.05 | C21: =$C$9*(1+B21) -> 0.8295 | D21: =$C$7/C21 -> 1380.3496 | E21: =D21-$C$8 -> 170.14961 | F21: =IF(D21=0,0,E21/D21) -> 0.12326559 | G21: =IF(F21<0,"Loss",IF(F21<$C$10,"Below floor","OK")) -> OK
B22: 0.075 | C22: =$C$9*(1+B22) -> 0.84925 | D22: =$C$7/C22 -> 1348.2485 | E22: =D22-$C$8 -> 138.04845 | F22: =IF(D22=0,0,E22/D22) -> 0.10239096 | G22: =IF(F22<0,"Loss",IF(F22<$C$10,"Below floor","OK")) -> OK
B23: 0.1 | C23: =$C$9*(1+B23) -> 0.869 | D23: =$C$7/C23 -> 1317.6064 | E23: =D23-$C$8 -> 107.40644 | F23: =IF(D23=0,0,E23/D23) -> 0.081516332 | G23: =IF(F23<0,"Loss",IF(F23<$C$10,"Below floor","OK")) -> OK

Sheet Orders
A1: Order lines (simulated, Oct 2025 - Sep 2026)
A2: Columns A-Q = raw data from the 'ERP'. Columns R-AH = formulas.
A4: Order ID | B4: Line | C4: Order date | D4: Month | E4: Customer | F4: Segment | G4: Rep | H4: Region | I4: SKU | J4: Qty | K4: List price (local) | L4: Quoted price (local) | M4: Approval logged | N4: FX book | O4: FX actual | P4: Book landed cost (USD) | Q4: Actual landed cost (USD) | R4: Category | S4: Discount % | T4: Revenue at list, book FX | U4: Revenue at book FX | V4: Discount impact | W4: Revenue (USD) | X4: FX impact | Y4: Book COGS | Z4: Actual COGS | AA4: Cost variance | AB4: Gross profit | AC4: Margin % | AD4: Target margin | AE4: Floor margin | AF4: Below floor | AG4: Unapproved below floor | AH4: Shortfall vs target
A5: SO-00001 | B5: 1 | C5: 2025-10-19 | D5: 2025-10 | E5: C025 | F5: SMB | G5: R01 | H5: DE | I5: L08 | J5: 5 | K5: 1655 | L5: 1652.26 | M5: N | N5: 0.92 | O5: 0.9166 | P5: 1504.8 | Q5: 1504.8 | R5: =INDEX(SKU_Master!$D$5:$D$34,MATCH($I5,SKU_Master!$A$5:$A$34,0)) -> Laptop | S5: =IF(K5=0,0,1-L5/K5) -> 0.0016555891 | T5: =J5*K5/N5 -> 8994.5652 | U5: =J5*L5/N5 -> 8979.6739 | V5: =U5-T5 -> -14.891304 | W5: =J5*L5/O5 -> 9012.9828 | X5: =W5-U5 -> 33.308849 | Y5: =J5*P5 -> 7524 | Z5: =J5*Q5 -> 7524 | AA5: =Y5-Z5 -> 0 | AB5: =W5-Z5 -> 1488.9828 | AC5: =IF(W5=0,0,AB5/W5) -> 0.16520422 | AD5: =INDEX(Assumptions!$B$14:$B$16,MATCH($R5,Assumptions!$A$14:$A$16,0)) -> 0.12 | AE5: =INDEX(Assumptions!$C$14:$C$16,MATCH($R5,Assumptions!$A$14:$A$16,0)) -> 0.08 | AF5: =IF(AC5<AE5,1,0) -> 0 | AG5: =IF(AND(AF5=1,M5="N"),1,0) -> 0 | AH5: =MAX(0,W5*AD5-AB5) -> 0
A6: SO-00001 | B6: 2 | C6: 2025-10-19 | D6: 2025-10 | E6: C025 | F6: SMB | G6: R01 | H6: DE | I6: M02 | J6: 3 | K6: 460 | L6: 451.37 | M6: N | N6: 0.92 | O6: 0.9166 | P6: 383.2 | Q6: 383.2 | R6: =INDEX(SKU_Master!$D$5:$D$34,MATCH($I6,SKU_Master!$A$5:$A$34,0)) -> Monitor | S6: =IF(K6=0,0,1-L6/K6) -> 0.01876087 | T6: =J6*K6/N6 -> 1500 | U6: =J6*L6/N6 -> 1471.8587 | V6: =U6-T6 -> -28.141304 | W6: =J6*L6/O6 -> 1477.3184 | X6: =W6-U6 -> 5.4596548 | Y6: =J6*P6 -> 1149.6 | Z6: =J6*Q6 -> 1149.6 | AA6: =Y6-Z6 -> 0 | AB6: =W6-Z6 -> 327.71835 | AC6: =IF(W6=0,0,AB6/W6) -> 0.22183326 | AD6: =INDEX(Assumptions!$B$14:$B$16,MATCH($R6,Assumptions!$A$14:$A$16,0)) -> 0.18 | AE6: =INDEX(Assumptions!$C$14:$C$16,MATCH($R6,Assumptions!$A$14:$A$16,0)) -> 0.12 | AF6: =IF(AC6<AE6,1,0) -> 0 | AG6: =IF(AND(AF6=1,M6="N"),1,0) -> 0 | AH6: =MAX(0,W6*AD6-AB6) -> 0
A7: SO-00002 | B7: 1 | C7: 2025-10-05 | D7: 2025-10 | E7: C020 | F7: Mid-market | G7: R02 | H7: UK | I7: L04 | J7: 19 | K7: 940 | L7: 913.47 | M7: N | N7: 0.79 | O7: 0.7893 | P7: 992.6 | Q7: 992.6 | R7: =INDEX(SKU_Master!$D$5:$D$34,MATCH($I7,SKU_Master!$A$5:$A$34,0)) -> Laptop | S7: =IF(K7=0,0,1-L7/K7) -> 0.028223404 | T7: =J7*K7/N7 -> 22607.595 | U7: =J7*L7/N7 -> 21969.532 | V7: =U7-T7 -> -638.06329 | W7: =J7*L7/O7 -> 21989.016 | X7: =W7-U7 -> 19.483938 | Y7: =J7*P7 -> 18859.4 | Z7: =J7*Q7 -> 18859.4 | AA7: =Y7-Z7 -> 0 | AB7: =W7-Z7 -> 3129.6156 | AC7: =IF(W7=0,0,AB7/W7) -> 0.14232632 | AD7: =INDEX(Assumptions!$B$14:$B$16,MATCH($R7,Assumptions!$A$14:$A$16,0)) -> 0.12 | AE7: =INDEX(Assumptions!$C$14:$C$16,MATCH($R7,Assumptions!$A$14:$A$16,0)) -> 0.08 | AF7: =IF(AC7<AE7,1,0) -> 0 | AG7: =IF(AND(AF7=1,M7="N"),1,0) -> 0 | AH7: =MAX(0,W7*AD7-AB7) -> 0
A8: SO-00002 | B8: 2 | C8: 2025-10-05 | D8: 2025-10 | E8: C020 | F8: Mid-market | G8: R02 | H8: UK | I8: M02 | J8: 7 | K8: 400 | L8: 384.43 | M8: N | N8: 0.79 | O8: 0.7893 | P8: 388.2 | Q8: 388.2 | R8: =INDEX(SKU_Master!$D$5:$D$34,MATCH($I8,SKU_Master!$A$5:$A$34,0)) -> Monitor | S8: =IF(K8=0,0,1-L8/K8) -> 0.038925 | T8: =J8*K8/N8 -> 3544.3038 | U8: =J8*L8/N8 -> 3406.3418 | V8: =U8-T8 -> -137.96203 | W8: =J8*L8/O8 -> 3409.3627 | X8: =W8-U8 -> 3.0209543 | Y8: =J8*P8 -> 2717.4 | Z8: =J8*Q8 -> 2717.4 | AA8: =Y8-Z8 -> 0 | AB8: =W8-Z8 -> 691.96273 | AC8: =IF(W8=0,0,AB8/W8) -> 0.20295955 | AD8: =INDEX(Assumptions!$B$14:$B$16,MATCH($R8,Assumptions!$A$14:$A$16,0)) -> 0.18 | AE8: =INDEX(Assumptions!$C$14:$C$16,MATCH($R8,Assumptions!$A$14:$A$16,0)) -> 0.12 | AF8: =IF(AC8<AE8,1,0) -> 0 | AG8: =IF(AND(AF8=1,M8="N"),1,0) -> 0 | AH8: =MAX(0,W8*AD8-AB8) -> 0
A9: SO-00002 | B9: 3 | C9: 2025-10-05 | D9: 2025-10 | E9: C020 | F9: Mid-market | G9: R02 | H9: UK | I9: A08 | J9: 9 | K9: 50 | L9: 48.53 | M9: N | N9: 0.79 | O9: 0.7893 | P9: 40 | Q9: 40 | R9: =INDEX(SKU_Master!$D$5:$D$34,MATCH($I9,SKU_Master!$A$5:$A$34,0)) -> Accessory | S9: =IF(K9=0,0,1-L9/K9) -> 0.0294 | T9: =J9*K9/N9 -> 569.62025 | U9: =J9*L9/N9 -> 552.87342 | V9: =U9-T9 -> -16.746835 | W9: =J9*L9/O9 -> 553.36374 | X9: =W9-U9 -> 0.4903223 | Y9: =J9*P9 -> 360 | Z9: =J9*Q9 -> 360 | AA9: =Y9-Z9 -> 0 | AB9: =W9-Z9 -> 193.36374 | AC9: =IF(W9=0,0,AB9/W9) -> 0.34943334 | AD9: =INDEX(Assumptions!$B$14:$B$16,MATCH($R9,Assumptions!$A$14:$A$16,0)) -> 0.32 | AE9: =INDEX(Assumptions!$C$14:$C$16,MATCH($R9,Assumptions!$A$14:$A$16,0)) -> 0.22 | AF9: =IF(AC9<AE9,1,0) -> 0 | AG9: =IF(AND(AF9=1,M9="N"),1,0) -> 0 | AH9: =MAX(0,W9*AD9-AB9) -> 0
A10: SO-00003 | B10: 1 | C10: 2025-10-04 | D10: 2025-10 | E10: C013 | F10: SMB | G10: R01 | H10: UK | I10: L08 | J10: 3 | K10: 1425 | L10: 1403.09 | M10: N | N10: 0.79 | O10: 0.7893 | P10: 1508.8 | Q10: 1508.8 | R10: =INDEX(SKU_Master!$D$5:$D$34,MATCH($I10,SKU_Master!$A$5:$A$34,0)) -> Laptop | S10: =IF(K10=0,0,1-L10/K10) -> 0.015375439 | T10: =J10*K10/N10 -> 5411.3924 | U10: =J10*L10/N10 -> 5328.1899 | V10: =U10-T10 -> -83.202532 | W10: =J10*L10/O10 -> 5332.9152 | X10: =W10-U10 -> 4.7253679 | Y10: =J10*P10 -> 4526.4 | Z10: =J10*Q10 -> 4526.4 | AA10: =Y10-Z10 -> 0 | AB10: =W10-Z10 -> 806.51524 | AC10: =IF(W10=0,0,AB10/W10) -> 0.15123346 | AD10: =INDEX(Assumptions!$B$14:$B$16,MATCH($R10,Assumptions!$A$14:$A$16,0)) -> 0.12 | AE10: =INDEX(Assumptions!$C$14:$C$16,MATCH($R10,Assumptions!$A$14:$A$16,0)) -> 0.08 | AF10: =IF(AC10<AE10,1,0) -> 0 | AG10: =IF(AND(AF10=1,M10="N"),1,0) -> 0 | AH10: =MAX(0,W10*AD10-AB10) -> 0
A11: SO-00003 | B11: 2 | C11: 2025-10-04 | D11: 2025-10 | E11: C013 | F11: SMB | G11: R01 | H11: UK | I11: A01 | J11: 3 | K11: 280 | L11: 278.71 | M11: N | N11: 0.79 | O11: 0.7893 | P11: 222.7 | Q11: 222.7 | R11: =INDEX(SKU_Master!$D$5:$D$34,MATCH($I11,SKU_Master!$A$5:$A$34,0)) -> Accessory | S11: =IF(K11=0,0,1-L11/K11) -> 0.0046071429 | T11: =J11*K11/N11 -> 1063.2911 | U11: =J11*L11/N11 -> 1058.3924 | V11: =U11-T11 -> -4.8987342 | W11: =J11*L11/O11 -> 1059.3311 | X11: =W11-U11 -> 0.93864777 | Y11: =J11*P11 -> 668.1 | Z11: =J11*Q11 -> 668.1 | AA11: =Y11-Z11 -> 0 | AB11: =W11-Z11 -> 391.23105 | AC11: =IF(W11=0,0,AB11/W11) -> 0.36931897 | AD11: =INDEX(Assumptions!$B$14:$B$16,MATCH($R11,Assumptions!$A$14:$A$16,0)) -> 0.32 | AE11: =INDEX(Assumptions!$C$14:$C$16,MATCH($R11,Assumptions!$A$14:$A$16,0)) -> 0.22 | AF11: =IF(AC11<AE11,1,0) -> 0 | AG11: =IF(AND(AF11=1,M11="N"),1,0) -> 0 | AH11: =MAX(0,W11*AD11-AB11) -> 0
A12: SO-00004 | B12: 1 | C12: 2025-10-08 | D12: 2025-10 | E12: C027 | F12: SMB | G12: R03 | H12: US | I12: L10 | J12: 2 | K12: 1365 | L12: 1342.93 | M12: N | N12: 1 | O12: 1 | P12: 1162.6 | Q12: 1162.6 | R12: =INDEX(SKU_Master!$D$5:$D$34,MATCH($I12,SKU_Master!$A$5:$A$34,0)) -> Laptop | S12: =IF(K12=0,0,1-L12/K12) -> 0.016168498 | T12: =J12*K12/N12 -> 2730 | U12: =J12*L12/N12 -> 2685.86 | V12: =U12-T12 -> -44.14 | W12: =J12*L12/O12 -> 2685.86 | X12: =W12-U12 -> 0 | Y12: =J12*P12 -> 2325.2 | Z12: =J12*Q12 -> 2325.2 | AA12: =Y12-Z12 -> 0 | AB12: =W12-Z12 -> 360.66 | AC12: =IF(W12=0,0,AB12/W12) -> 0.13428101 | AD12: =INDEX(Assumptions!$B$14:$B$16,MATCH($R12,Assumptions!$A$14:$A$16,0)) -> 0.12 | AE12: =INDEX(Assumptions!$C$14:$C$16,MATCH($R12,Assumptions!$A$14:$A$16,0)) -> 0.08 | AF12: =IF(AC12<AE12,1,0) -> 0 | AG12: =IF(AND(AF12=1,M12="N"),1,0) -> 0 | AH12: =MAX(0,W12*AD12-AB12) -> 0
A13: SO-00004 | B13: 2 | C13: 2025-10-08 | D13: 2025-10 | E13: C027 | F13: SMB | G13: R03 | H13: US | I13: A03 | J13: 2 | K13: 135 | L13: 134.21 | M13: N | N13: 1 | O13: 1 | P13: 86 | Q13: 86 | R13: =INDEX(SKU_Master!$D$5:$D$34,MATCH($I13,SKU_Master!$A$5:$A$34,0)) -> Accessory | S13: =IF(K13=0,0,1-L13/K13) -> 0.0058518519 | T13: =J13*K13/N13 -> 270 | U13: =J13*L13/N13 -> 268.42 | V13: =U13-T13 -> -1.58 | W13: =J13*L13/O13 -> 268.42 | X13: =W13-U13 -> 0 | Y13: =J13*P13 -> 172 | Z13: =J13*Q13 -> 172 | AA13: =Y13-Z13 -> 0 | AB13: =W13-Z13 -> 96.42 | AC13: =IF(W13=0,0,AB13/W13) -> 0.35921317 | AD13: =INDEX(Assumptions!$B$14:$B$16,MATCH($R13,Assumptions!$A$14:$A$16,0)) -> 0.32 | AE13: =INDEX(Assumptions!$C$14:$C$16,MATCH($R13,Assumptions!$A$14:$A$16,0)) -> 0.22 | AF13: =IF(AC13<AE13,1,0) -> 0 | AG13: =IF(AND(AF13=1,M13="N"),1,0) -> 0 | AH13: =MAX(0,W13*AD13-AB13) -> 0
A14: SO-00005 | B14: 1 | C14: 2025-10-16 | D14: 2025-10 | E14: C025 | F14: SMB | G14: R01 | H14: DE | I14: L01 | J14: 3 | K14: 1325 | L14: 1313.47 | M14: N | N14: 0.92 | O14: 0.9166 | P14: 1206.2 | Q14: 1206.2 | R14: =INDEX(SKU_Master!$D$5:$D$34,MATCH($I14,SKU_Master!$A$5:$A$34,0)) -> Laptop | S14: =IF(K14=0,0,1-L14/K14) -> 0.0087018868 | T14: =J14*K14/N14 -> 4320.6522 | U14: =J14*L14/N14 -> 4283.0543 | V14: =U14-T14 -> -37.597826 | W14: =J14*L14/O14 -> 4298.9417 | X14: =W14-U14 -> 15.887393 | Y14: =J14*P14 -> 3618.6 | Z14: =J14*Q14 -> 3618.6 | AA14: =Y14-Z14 -> 0 | AB14: =W14-Z14 -> 680.34174 | AC14: =IF(W14=0,0,AB14/W14) -> 0.15825796 | AD14: =INDEX(Assumptions!$B$14:$B$16,MATCH($R14,Assumptions!$A$14:$A$16,0)) -> 0.12 | AE14: =INDEX(Assumptions!$C$14:$C$16,MATCH($R14,Assumptions!$A$14:$A$16,0)) -> 0.08 | AF14: =IF(AC14<AE14,1,0) -> 0 | AG14: =IF(AND(AF14=1,M14="N"),1,0) -> 0 | AH14: =MAX(0,W14*AD14-AB14) -> 0
A15: SO-00005 | B15: 2 | C15: 2025-10-16 | D15: 2025-10 | E15: C025 | F15: SMB | G15: R01 | H15: DE | I15: M05 | J15: 3 | K15: 250 | L15: 246.26 | M15: N | N15: 0.92 | O15: 0.9166 | P15: 206.8 | Q15: 206.8 | R15: =INDEX(SKU_Master!$D$5:$D$34,MATCH($I15,SKU_Master!$A$5:$A$34,0)) -> Monitor | S15: =IF(K15=0,0,1-L15/K15) -> 0.01496 | T15: =J15*K15/N15 -> 815.21739 | U15: =J15*L15/N15 -> 803.02174 | V15: =U15-T15 -> -12.195652 | W15: =J15*L15/O15 -> 806.00044 | X15: =W15-U15 -> 2.9786973 | Y15: =J15*P15 -> 620.4 | Z15: =J15*Q15 -> 620.4 | AA15: =Y15-Z15 -> 0 | AB15: =W15-Z15 -> 185.60044 | AC15: =IF(W15=0,0,AB15/W15) -> 0.23027337 | AD15: =INDEX(Assumptions!$B$14:$B$16,MATCH($R15,Assumptions!$A$14:$A$16,0)) -> 0.18 | AE15: =INDEX(Assumptions!$C$14:$C$16,MATCH($R15,Assumptions!$A$14:$A$16,0)) -> 0.12 | AF15: =IF(AC15<AE15,1,0) -> 0 | AG15: =IF(AND(AF15=1,M15="N"),1,0) -> 0 | AH15: =MAX(0,W15*AD15-AB15) -> 0
A16: SO-00006 | B16: 1 | C16: 2025-10-27 | D16: 2025-10 | E16: C007 | F16: SMB | G16: R01 | H16: DE | I16: L03 | J16: 9 | K16: 3250 | L16: 3199.82 | M16: N | N16: 0.92 | O16: 0.9166 | P16: 2958.5 | Q16: 2958.5 | R16: =INDEX(SKU_Master!$D$5:$D$34,MATCH($I16,SKU_Master!$A$5:$A$34,0)) -> Laptop | S16: =IF(K16=0,0,1-L16/K16) -> 0.01544 | T16: =J16*K16/N16 -> 31793.478 | U16: =J16*L16/N16 -> 31302.587 | V16: =U16-T16 -> -490.8913 | W16: =J16*L16/O16 -> 31418.7 | X16: =W16-U16 -> 116.11259 | Y16: =J16*P16 -> 26626.5 | Z16: =J16*Q16 -> 26626.5 | AA16: =Y16-Z16 -> 0 | AB16: =W16-Z16 -> 4792.1995 | AC16: =IF(W16=0,0,AB16/W16) -> 0.15252699 | AD16: =INDEX(Assumptions!$B$14:$B$16,MATCH($R16,Assumptions!$A$14:$A$16,0)) -> 0.12 | AE16: =INDEX(Assumptions!$C$14:$C$16,MATCH($R16,Assumptions!$A$14:$A$16,0)) -> 0.08 | AF16: =IF(AC16<AE16,1,0) -> 0 | AG16: =IF(AND(AF16=1,M16="N"),1,0) -> 0 | AH16: =MAX(0,W16*AD16-AB16) -> 0
... A1965: SO-00871 | B1965: 3 | C1965: 2026-09-14 | D1965: 2026-09 | E1965: C011 | F1965: Mid-market | G1965: R05 | H1965: US | I1965: A04 | J1965: 3 | K1965: 120 | L1965: 117.83 | M1965: N | N1965: 1 | O1965: 1 | P1965: 76 | Q1965: 76 | R1965: =INDEX(SKU_Master!$D$5:$D$34,MATCH($I1965,SKU_Master!$A$5:$A$34,0)) -> Accessory | S1965: =IF(K1965=0,0,1-L1965/K1965) -> 0.018083333 | T1965: =J1965*K1965/N1965 -> 360 | U1965: =J1965*L1965/N1965 -> 353.49 | V1965: =U1965-T1965 -> -6.51 | W1965: =J1965*L1965/O1965 -> 353.49 | X1965: =W1965-U1965 -> 0 | Y1965: =J1965*P1965 -> 228 | Z1965: =J1965*Q1965 -> 228 | AA1965: =Y1965-Z1965 -> 0 | AB1965: =W1965-Z1965 -> 125.49 | AC1965: =IF(W1965=0,0,AB1965/W1965) -> 0.35500297 | AD1965: =INDEX(Assumptions!$B$14:$B$16,MATCH($R1965,Assumptions!$A$14:$A$16,0)) -> 0.32 | AE1965: =INDEX(Assumptions!$C$14:$C$16,MATCH($R1965,Assumptions!$A$14:$A$16,0)) -> 0.22 | AF1965: =IF(AC1965<AE1965,1,0) -> 0 | AG1965: =IF(AND(AF1965=1,M1965="N"),1,0) -> 0 | AH1965: =MAX(0,W1965*AD1965-AB1965) -> 0

Sheet Margin_Leakage
A1: Margin Leakage Analysis
A2: Where did margin go between the price book and the invoice? All numbers in USD, from the Orders sheet.
A4: 1. Margin bridge: list price -> actual gross profit | E4: Headline KPIs
A5: Step | B5: USD | C5: % of revenue at list | E5: Revenue (USD) | F5: =SUM(Orders!$W$5:$W$1965) -> 26674169
A6: Gross profit at list price (book cost & FX) | B6: =SUM(Orders!$T$5:$T$1965)-SUM(Orders!$Y$5:$Y$1965) -> 4911096.7 | C6: =IF(SUM(Orders!$T$5:$T$1965)=0,0,B6/SUM(Orders!$T$5:$T$1965)) -> 0.17658515 | E6: Gross profit (USD) | F6: =SUM(Orders!$AB$5:$AB$1965) -> 3606534.9
A7: - Discounts given | B7: =SUM(Orders!$V$5:$V$1965) -> -1010095.3 | C7: =IF(SUM(Orders!$T$5:$T$1965)=0,0,B7/SUM(Orders!$T$5:$T$1965)) -> -0.036319347 | E7: Gross margin % | F7: =IF(F5=0,0,F6/F5) -> 0.13520702
A8: of which: unapproved below-floor lines | B8: =SUMIFS(Orders!$V$5:$V$1965,Orders!$AG$5:$AG$1965,1) -> -129472.32 | C8: =IF(SUM(Orders!$T$5:$T$1965)=0,0,B8/SUM(Orders!$T$5:$T$1965)) -> -0.0046553531 | E8: Target margin % (revenue-weighted) | F8: =IF(F5=0,0,SUMPRODUCT(Orders!$W$5:$W$1965,Orders!$AD$5:$AD$1965)/F5) -> 0.13783788
A9: - Vendor cost increases not in price book | B9: =SUM(Orders!$AA$5:$AA$1965) -> -167238.03 | C9: =IF(SUM(Orders!$T$5:$T$1965)=0,0,B9/SUM(Orders!$T$5:$T$1965)) -> -0.0060132705 | E9: Shortfall vs target (USD) | F9: =SUM(Orders!$AH$5:$AH$1965) -> 305416.92
A10: - FX movement vs book rate | B10: =SUM(Orders!$X$5:$X$1965) -> -127228.5 | C10: =IF(SUM(Orders!$T$5:$T$1965)=0,0,B10/SUM(Orders!$T$5:$T$1965)) -> -0.0045746735 | E10: Order lines below floor | F10: =SUM(Orders!$AF$5:$AF$1965) -> 52
A11: Actual gross profit | B11: =B6+B7+B9+B10 -> 3606534.9 | C11: =IF(SUM(Orders!$T$5:$T$1965)=0,0,B11/SUM(Orders!$T$5:$T$1965)) -> 0.12967786 | E11: of which no approval logged | F11: =SUM(Orders!$AG$5:$AG$1965) -> 48
A12: Check: equals sum of order-line gross profit (should be 0) | B12: =ROUND(B11-SUM(Orders!$AB$5:$AB$1965),2) -> 0 | C12: =IF(SUM(Orders!$T$5:$T$1965)=0,0,B12/SUM(Orders!$T$5:$T$1965)) -> 0 | E12: Revenue on unapproved below-floor lines | F12: =SUMIFS(Orders!$W$5:$W$1965,Orders!$AG$5:$AG$1965,1) -> 2073328.7
A15: 2. By region
B16: Revenue | C16: Gross profit | D16: Margin % | E16: Target % | F16: Gap (pts) | G16: Shortfall vs target | H16: Discount impact | I16: Cost variance | J16: FX impact | K16: Lines below floor | L16: Unapproved
A17: US | B17: =SUMIFS(Orders!$W$5:$W$1965,Orders!$H$5:$H$1965,$A17) -> 9851879.2 | C17: =SUMIFS(Orders!$AB$5:$AB$1965,Orders!$H$5:$H$1965,$A17) -> 1311949.8 | D17: =IF(B17=0,0,C17/B17) -> 0.13316747 | E17: =IF(B17=0,0,SUMPRODUCT((Orders!$H$5:$H$1965=$A17)*Orders!$W$5:$W$1965*Orders!$AD$5:$AD$1965)/B17) -> 0.13766458 | F17: =(D17-E17)*100 -> -0.44971152 | G17: =SUMIFS(Orders!$AH$5:$AH$1965,Orders!$H$5:$H$1965,$A17) -> 112503.25 | H17: =SUMIFS(Orders!$V$5:$V$1965,Orders!$H$5:$H$1965,$A17) -> -351380.79 | I17: =SUMIFS(Orders!$AA$5:$AA$1965,Orders!$H$5:$H$1965,$A17) -> -34766.66 | J17: =SUMIFS(Orders!$X$5:$X$1965,Orders!$H$5:$H$1965,$A17) -> 0 | K17: =SUMIFS(Orders!$AF$5:$AF$1965,Orders!$H$5:$H$1965,$A17) -> 25 | L17: =SUMIFS(Orders!$AG$5:$AG$1965,Orders!$H$5:$H$1965,$A17) -> 23
A18: UK | B18: =SUMIFS(Orders!$W$5:$W$1965,Orders!$H$5:$H$1965,$A18) -> 2330583.7 | C18: =SUMIFS(Orders!$AB$5:$AB$1965,Orders!$H$5:$H$1965,$A18) -> 297738.44 | D18: =IF(B18=0,0,C18/B18) -> 0.12775273 | E18: =IF(B18=0,0,SUMPRODUCT((Orders!$H$5:$H$1965=$A18)*Orders!$W$5:$W$1965*Orders!$AD$5:$AD$1965)/B18) -> 0.13532315 | F18: =(D18-E18)*100 -> -0.75704209 | G18: =SUMIFS(Orders!$AH$5:$AH$1965,Orders!$H$5:$H$1965,$A18) -> 37160.127 | H18: =SUMIFS(Orders!$V$5:$V$1965,Orders!$H$5:$H$1965,$A18) -> -104191.13 | I18: =SUMIFS(Orders!$AA$5:$AA$1965,Orders!$H$5:$H$1965,$A18) -> -6023.7 | J18: =SUMIFS(Orders!$X$5:$X$1965,Orders!$H$5:$H$1965,$A18) -> -40731.463 | K18: =SUMIFS(Orders!$AF$5:$AF$1965,Orders!$H$5:$H$1965,$A18) -> 5 | L18: =SUMIFS(Orders!$AG$5:$AG$1965,Orders!$H$5:$H$1965,$A18) -> 4
A19: DE | B19: =SUMIFS(Orders!$W$5:$W$1965,Orders!$H$5:$H$1965,$A19) -> 7807689.3 | C19: =SUMIFS(Orders!$AB$5:$AB$1965,Orders!$H$5:$H$1965,$A19) -> 1121149.5 | D19: =IF(B19=0,0,C19/B19) -> 0.14359555 | E19: =IF(B19=0,0,SUMPRODUCT((Orders!$H$5:$H$1965=$A19)*Orders!$W$5:$W$1965*Orders!$AD$5:$AD$1965)/B19) -> 0.13925943 | F19: =(D19-E19)*100 -> 0.43361263 | G19: =SUMIFS(Orders!$AH$5:$AH$1965,Orders!$H$5:$H$1965,$A19) -> 63583.764 | H19: =SUMIFS(Orders!$V$5:$V$1965,Orders!$H$5:$H$1965,$A19) -> -318630.62 | I19: =SUMIFS(Orders!$AA$5:$AA$1965,Orders!$H$5:$H$1965,$A19) -> -28377.52 | J19: =SUMIFS(Orders!$X$5:$X$1965,Orders!$H$5:$H$1965,$A19) -> -37690.921 | K19: =SUMIFS(Orders!$AF$5:$AF$1965,Orders!$H$5:$H$1965,$A19) -> 8 | L19: =SUMIFS(Orders!$AG$5:$AG$1965,Orders!$H$5:$H$1965,$A19) -> 7
A20: CA | B20: =SUMIFS(Orders!$W$5:$W$1965,Orders!$H$5:$H$1965,$A20) -> 1557366.6 | C20: =SUMIFS(Orders!$AB$5:$AB$1965,Orders!$H$5:$H$1965,$A20) -> 253459.16 | D20: =IF(B20=0,0,C20/B20) -> 0.16274855 | E20: =IF(B20=0,0,SUMPRODUCT((Orders!$H$5:$H$1965=$A20)*Orders!$W$5:$W$1965*Orders!$AD$5:$AD$1965)/B20) -> 0.13752054 | F20: =(D20-E20)*100 -> 2.5228014 | G20: =SUMIFS(Orders!$AH$5:$AH$1965,Orders!$H$5:$H$1965,$A20) -> 1392.7131 | H20: =SUMIFS(Orders!$V$5:$V$1965,Orders!$H$5:$H$1965,$A20) -> -33920.993 | I20: =SUMIFS(Orders!$AA$5:$AA$1965,Orders!$H$5:$H$1965,$A20) -> -3221.6 | J20: =SUMIFS(Orders!$X$5:$X$1965,Orders!$H$5:$H$1965,$A20) -> 1681.7674 | K20: =SUMIFS(Orders!$AF$5:$AF$1965,Orders!$H$5:$H$1965,$A20) -> 0 | L20: =SUMIFS(Orders!$AG$5:$AG$1965,Orders!$H$5:$H$1965,$A20) -> 0
A21: IN | B21: =SUMIFS(Orders!$W$5:$W$1965,Orders!$H$5:$H$1965,$A21) -> 5126650.5 | C21: =SUMIFS(Orders!$AB$5:$AB$1965,Orders!$H$5:$H$1965,$A21) -> 622238.04 | D21: =IF(B21=0,0,C21/B21) -> 0.12137321 | E21: =IF(B21=0,0,SUMPRODUCT((Orders!$H$5:$H$1965=$A21)*Orders!$W$5:$W$1965*Orders!$AD$5:$AD$1965)/B21) -> 0.13724555 | F21: =(D21-E21)*100 -> -1.5872333 | G21: =SUMIFS(Orders!$AH$5:$AH$1965,Orders!$H$5:$H$1965,$A21) -> 90777.064 | H21: =SUMIFS(Orders!$V$5:$V$1965,Orders!$H$5:$H$1965,$A21) -> -201971.73 | I21: =SUMIFS(Orders!$AA$5:$AA$1965,Orders!$H$5:$H$1965,$A21) -> -94848.55 | J21: =SUMIFS(Orders!$X$5:$X$1965,Orders!$H$5:$H$1965,$A21) -> -50487.885 | K21: =SUMIFS(Orders!$AF$5:$AF$1965,Orders!$H$5:$H$1965,$A21) -> 14 | L21: =SUMIFS(Orders!$AG$5:$AG$1965,Orders!$H$5:$H$1965,$A21) -> 14
A24: 3. By category
B25: Revenue | C25: Gross profit | D25: Margin % | E25: Target % | F25: Gap (pts) | G25: Shortfall vs target | H25: Discount impact | I25: Cost variance | J25: FX impact | K25: Lines below floor | L25: Unapproved
A26: Laptop | B26: =SUMIFS(Orders!$W$5:$W$1965,Orders!$R$5:$R$1965,$A26) -> 22557038 | C26: =SUMIFS(Orders!$AB$5:$AB$1965,Orders!$R$5:$R$1965,$A26) -> 2608607.9 | D26: =IF(B26=0,0,C26/B26) -> 0.11564497 | E26: =IF(B26=0,0,SUMPRODUCT((Orders!$R$5:$R$1965=$A26)*Orders!$W$5:$W$1965*Orders!$AD$5:$AD$1965)/B26) -> 0.12 | F26: =(D26-E26)*100 -> -0.43550343 | G26: =SUMIFS(Orders!$AH$5:$AH$1965,Orders!$R$5:$R$1965,$A26) -> 271851.04 | H26: =SUMIFS(Orders!$V$5:$V$1965,Orders!$R$5:$R$1965,$A26) -> -845196.47 | I26: =SUMIFS(Orders!$AA$5:$AA$1965,Orders!$R$5:$R$1965,$A26) -> -135668.03 | J26: =SUMIFS(Orders!$X$5:$X$1965,Orders!$R$5:$R$1965,$A26) -> -106387.33 | K26: =SUMIFS(Orders!$AF$5:$AF$1965,Orders!$R$5:$R$1965,$A26) -> 47 | L26: =SUMIFS(Orders!$AG$5:$AG$1965,Orders!$R$5:$R$1965,$A26) -> 43
A27: Monitor | B27: =SUMIFS(Orders!$W$5:$W$1965,Orders!$R$5:$R$1965,$A27) -> 2482968.7 | C27: =SUMIFS(Orders!$AB$5:$AB$1965,Orders!$R$5:$R$1965,$A27) -> 452381.17 | D27: =IF(B27=0,0,C27/B27) -> 0.18219367 | E27: =IF(B27=0,0,SUMPRODUCT((Orders!$R$5:$R$1965=$A27)*Orders!$W$5:$W$1965*Orders!$AD$5:$AD$1965)/B27) -> 0.18 | F27: =(D27-E27)*100 -> 0.21936683 | G27: =SUMIFS(Orders!$AH$5:$AH$1965,Orders!$R$5:$R$1965,$A27) -> 25921.536 | H27: =SUMIFS(Orders!$V$5:$V$1965,Orders!$R$5:$R$1965,$A27) -> -97342.033 | I27: =SUMIFS(Orders!$AA$5:$AA$1965,Orders!$R$5:$R$1965,$A27) -> -24620 | J27: =SUMIFS(Orders!$X$5:$X$1965,Orders!$R$5:$R$1965,$A27) -> -13633.924 | K27: =SUMIFS(Orders!$AF$5:$AF$1965,Orders!$R$5:$R$1965,$A27) -> 5 | L27: =SUMIFS(Orders!$AG$5:$AG$1965,Orders!$R$5:$R$1965,$A27) -> 5
A28: Accessory | B28: =SUMIFS(Orders!$W$5:$W$1965,Orders!$R$5:$R$1965,$A28) -> 1634162.5 | C28: =SUMIFS(Orders!$AB$5:$AB$1965,Orders!$R$5:$R$1965,$A28) -> 545545.82 | D28: =IF(B28=0,0,C28/B28) -> 0.33383817 | E28: =IF(B28=0,0,SUMPRODUCT((Orders!$R$5:$R$1965=$A28)*Orders!$W$5:$W$1965*Orders!$AD$5:$AD$1965)/B28) -> 0.32 | F28: =(D28-E28)*100 -> 1.3838172 | G28: =SUMIFS(Orders!$AH$5:$AH$1965,Orders!$R$5:$R$1965,$A28) -> 7644.3442 | H28: =SUMIFS(Orders!$V$5:$V$1965,Orders!$R$5:$R$1965,$A28) -> -67556.758 | I28: =SUMIFS(Orders!$AA$5:$AA$1965,Orders!$R$5:$R$1965,$A28) -> -6950 | J28: =SUMIFS(Orders!$X$5:$X$1965,Orders!$R$5:$R$1965,$A28) -> -7207.2505 | K28: =SUMIFS(Orders!$AF$5:$AF$1965,Orders!$R$5:$R$1965,$A28) -> 0 | L28: =SUMIFS(Orders!$AG$5:$AG$1965,Orders!$R$5:$R$1965,$A28) -> 0
A31: 4. By sales rep
B32: Revenue | C32: Gross profit | D32: Margin % | E32: Target % | F32: Gap (pts) | G32: Shortfall vs target | H32: Discount impact | I32: Cost variance | J32: FX impact | K32: Lines below floor | L32: Unapproved
A33: R01 | B33: =SUMIFS(Orders!$W$5:$W$1965,Orders!$G$5:$G$1965,$A33) -> 2409561 | C33: =SUMIFS(Orders!$AB$5:$AB$1965,Orders!$G$5:$G$1965,$A33) -> 376745.1 | D33: =IF(B33=0,0,C33/B33) -> 0.15635425 | E33: =IF(B33=0,0,SUMPRODUCT((Orders!$G$5:$G$1965=$A33)*Orders!$W$5:$W$1965*Orders!$AD$5:$AD$1965)/B33) -> 0.13509998 | F33: =(D33-E33)*100 -> 2.1254276 | G33: =SUMIFS(Orders!$AH$5:$AH$1965,Orders!$G$5:$G$1965,$A33) -> 5483.3862 | H33: =SUMIFS(Orders!$V$5:$V$1965,Orders!$G$5:$G$1965,$A33) -> -43943.136 | I33: =SUMIFS(Orders!$AA$5:$AA$1965,Orders!$G$5:$G$1965,$A33) -> -5643.2 | J33: =SUMIFS(Orders!$X$5:$X$1965,Orders!$G$5:$G$1965,$A33) -> -4827.7916 | K33: =SUMIFS(Orders!$AF$5:$AF$1965,Orders!$G$5:$G$1965,$A33) -> 1 | L33: =SUMIFS(Orders!$AG$5:$AG$1965,Orders!$G$5:$G$1965,$A33) -> 1
A34: R02 | B34: =SUMIFS(Orders!$W$5:$W$1965,Orders!$G$5:$G$1965,$A34) -> 4718356.7 | C34: =SUMIFS(Orders!$AB$5:$AB$1965,Orders!$G$5:$G$1965,$A34) -> 657229.73 | D34: =IF(B34=0,0,C34/B34) -> 0.13929208 | E34: =IF(B34=0,0,SUMPRODUCT((Orders!$G$5:$G$1965=$A34)*Orders!$W$5:$W$1965*Orders!$AD$5:$AD$1965)/B34) -> 0.13785319 | F34: =(D34-E34)*100 -> 0.14388918 | G34: =SUMIFS(Orders!$AH$5:$AH$1965,Orders!$G$5:$G$1965,$A34) -> 35857.016 | H34: =SUMIFS(Orders!$V$5:$V$1965,Orders!$G$5:$G$1965,$A34) -> -136570.77 | I34: =SUMIFS(Orders!$AA$5:$AA$1965,Orders!$G$5:$G$1965,$A34) -> -49010.13 | J34: =SUMIFS(Orders!$X$5:$X$1965,Orders!$G$5:$G$1965,$A34) -> -31678.172 | K34: =SUMIFS(Orders!$AF$5:$AF$1965,Orders!$G$5:$G$1965,$A34) -> 9 | L34: =SUMIFS(Orders!$AG$5:$AG$1965,Orders!$G$5:$G$1965,$A34) -> 9
A35: R03 | B35: =SUMIFS(Orders!$W$5:$W$1965,Orders!$G$5:$G$1965,$A35) -> 1762095 | C35: =SUMIFS(Orders!$AB$5:$AB$1965,Orders!$G$5:$G$1965,$A35) -> 261598.14 | D35: =IF(B35=0,0,C35/B35) -> 0.14845859 | E35: =IF(B35=0,0,SUMPRODUCT((Orders!$G$5:$G$1965=$A35)*Orders!$W$5:$W$1965*Orders!$AD$5:$AD$1965)/B35) -> 0.13624677 | F35: =(D35-E35)*100 -> 1.2211811 | G35: =SUMIFS(Orders!$AH$5:$AH$1965,Orders!$G$5:$G$1965,$A35) -> 5792.4222 | H35: =SUMIFS(Orders!$V$5:$V$1965,Orders!$G$5:$G$1965,$A35) -> -31516.901 | I35: =SUMIFS(Orders!$AA$5:$AA$1965,Orders!$G$5:$G$1965,$A35) -> -5235.36 | J35: =SUMIFS(Orders!$X$5:$X$1965,Orders!$G$5:$G$1965,$A35) -> 212.20441 | K35: =SUMIFS(Orders!$AF$5:$AF$1965,Orders!$G$5:$G$1965,$A35) -> 2 | L35: =SUMIFS(Orders!$AG$5:$AG$1965,Orders!$G$5:$G$1965,$A35) -> 2
A36: R04 | B36: =SUMIFS(Orders!$W$5:$W$1965,Orders!$G$5:$G$1965,$A36) -> 12016501 | C36: =SUMIFS(Orders!$AB$5:$AB$1965,Orders!$G$5:$G$1965,$A36) -> 1479091 | D36: =IF(B36=0,0,C36/B36) -> 0.12308832 | E36: =IF(B36=0,0,SUMPRODUCT((Orders!$G$5:$G$1965=$A36)*Orders!$W$5:$W$1965*Orders!$AD$5:$AD$1965)/B36) -> 0.138254 | F36: =(D36-E36)*100 -> -1.5165673 | G36: =SUMIFS(Orders!$AH$5:$AH$1965,Orders!$G$5:$G$1965,$A36) -> 226235.71 | H36: =SUMIFS(Orders!$V$5:$V$1965,Orders!$G$5:$G$1965,$A36) -> -632849.18 | I36: =SUMIFS(Orders!$AA$5:$AA$1965,Orders!$G$5:$G$1965,$A36) -> -63125.42 | J36: =SUMIFS(Orders!$X$5:$X$1965,Orders!$G$5:$G$1965,$A36) -> -68891.357 | K36: =SUMIFS(Orders!$AF$5:$AF$1965,Orders!$G$5:$G$1965,$A36) -> 32 | L36: =SUMIFS(Orders!$AG$5:$AG$1965,Orders!$G$5:$G$1965,$A36) -> 28
A37: R05 | B37: =SUMIFS(Orders!$W$5:$W$1965,Orders!$G$5:$G$1965,$A37) -> 1438039.9 | C37: =SUMIFS(Orders!$AB$5:$AB$1965,Orders!$G$5:$G$1965,$A37) -> 200778.44 | D37: =IF(B37=0,0,C37/B37) -> 0.13961952 | E37: =IF(B37=0,0,SUMPRODUCT((Orders!$G$5:$G$1965=$A37)*Orders!$W$5:$W$1965*Orders!$AD$5:$AD$1965)/B37) -> 0.13795592 | F37: =(D37-E37)*100 -> 0.16635977 | G37: =SUMIFS(Orders!$AH$5:$AH$1965,Orders!$G$5:$G$1965,$A37) -> 9972.9817 | H37: =SUMIFS(Orders!$V$5:$V$1965,Orders!$G$5:$G$1965,$A37) -> -36195.21 | I37: =SUMIFS(Orders!$AA$5:$AA$1965,Orders!$G$5:$G$1965,$A37) -> -11935.34 | J37: =SUMIFS(Orders!$X$5:$X$1965,Orders!$G$5:$G$1965,$A37) -> -5449.2341 | K37: =SUMIFS(Orders!$AF$5:$AF$1965,Orders!$G$5:$G$1965,$A37) -> 3 | L37: =SUMIFS(Orders!$AG$5:$AG$1965,Orders!$G$5:$G$1965,$A37) -> 3
A38: R06 | B38: =SUMIFS(Orders!$W$5:$W$1965,Orders!$G$5:$G$1965,$A38) -> 4329615.6 | C38: =SUMIFS(Orders!$AB$5:$AB$1965,Orders!$G$5:$G$1965,$A38) -> 631092.53 | D38: =IF(B38=0,0,C38/B38) -> 0.14576179 | E38: =IF(B38=0,0,SUMPRODUCT((Orders!$G$5:$G$1965=$A38)*Orders!$W$5:$W$1965*Orders!$AD$5:$AD$1965)/B38) -> 0.13879838 | F38: =(D38-E38)*100 -> 0.69634173 | G38: =SUMIFS(Orders!$AH$5:$AH$1965,Orders!$G$5:$G$1965,$A38) -> 22075.407 | H38: =SUMIFS(Orders!$V$5:$V$1965,Orders!$G$5:$G$1965,$A38) -> -129020.07 | I38: =SUMIFS(Orders!$AA$5:$AA$1965,Orders!$G$5:$G$1965,$A38) -> -32288.58 | J38: =SUMIFS(Orders!$X$5:$X$1965,Orders!$G$5:$G$1965,$A38) -> -16594.151 | K38: =SUMIFS(Orders!$AF$5:$AF$1965,Orders!$G$5:$G$1965,$A38) -> 5 | L38: =SUMIFS(Orders!$AG$5:$AG$1965,Orders!$G$5:$G$1965,$A38) -> 5
A41: 5. By month
B42: Revenue | C42: Gross profit | D42: Margin % | E42: Target % | F42: Gap (pts) | G42: Shortfall vs target | H42: Discount impact | I42: Cost variance | J42: FX impact | K42: Lines below floor | L42: Unapproved
A43: 2025-10 | B43: =SUMIFS(Orders!$W$5:$W$1965,Orders!$D$5:$D$1965,$A43) -> 2095330.7 | C43: =SUMIFS(Orders!$AB$5:$AB$1965,Orders!$D$5:$D$1965,$A43) -> 295921.64 | D43: =IF(B43=0,0,C43/B43) -> 0.14122908 | E43: =IF(B43=0,0,SUMPRODUCT((Orders!$D$5:$D$1965=$A43)*Orders!$W$5:$W$1965*Orders!$AD$5:$AD$1965)/B43) -> 0.13498206 | F43: =(D43-E43)*100 -> 0.62470248 | G43: =SUMIFS(Orders!$AH$5:$AH$1965,Orders!$D$5:$D$1965,$A43) -> 13828.993 | H43: =SUMIFS(Orders!$V$5:$V$1965,Orders!$D$5:$D$1965,$A43) -> -71535.245 | I43: =SUMIFS(Orders!$AA$5:$AA$1965,Orders!$D$5:$D$1965,$A43) -> -7335 | J43: =SUMIFS(Orders!$X$5:$X$1965,Orders!$D$5:$D$1965,$A43) -> 532.60238 | K43: =SUMIFS(Orders!$AF$5:$AF$1965,Orders!$D$5:$D$1965,$A43) -> 3 | L43: =SUMIFS(Orders!$AG$5:$AG$1965,Orders!$D$5:$D$1965,$A43) -> 2
